[2025-07-27 21:45:39,921.921] _internal.py -> _log line:97 [INFO]: [31m[1mWARNING: This is a development server. Do not use it in a production deployment. Use a production WSGI server instead.[0m
 * Running on http://127.0.0.1:5000
[2025-07-27 21:45:39,921.921] _internal.py -> _log line:97 [INFO]: [33mPress CTRL+C to quit[0m
[2025-07-27 21:45:39,922.922] _internal.py -> _log line:97 [INFO]:  * Restarting with stat
[2025-07-27 21:45:42,307.307] _internal.py -> _log line:97 [WARNING]:  * Debugger is active!
[2025-07-27 21:45:42,324.324] _internal.py -> _log line:97 [INFO]:  * Debugger PIN: 222-154-992
[2025-07-27 21:46:23,723.723] _internal.py -> _log line:97 [INFO]: 127.0.0.1 - - [27/Jul/2025 21:46:23] "GET /ping HTTP/1.1" 200 -
[2025-07-27 21:48:28,171.171] _internal.py -> _log line:97 [INFO]:  * Detected change in '/Users/icourt1/Desktop/code/llmops/llmops-api/internal/router/router.py', reloading
[2025-07-27 21:48:28,720.720] _internal.py -> _log line:97 [INFO]:  * Restarting with stat
[2025-07-27 21:48:31,562.562] _internal.py -> _log line:97 [WARNING]:  * Debugger is active!
[2025-07-27 21:48:31,576.576] _internal.py -> _log line:97 [INFO]:  * Debugger PIN: 222-154-992
[2025-07-27 21:48:36,844.844] _internal.py -> _log line:97 [INFO]:  * Detected change in '/Users/icourt1/Desktop/code/llmops/llmops-api/internal/router/router.py', reloading
[2025-07-27 21:48:37,192.192] _internal.py -> _log line:97 [INFO]:  * Restarting with stat
[2025-07-27 21:48:39,920.920] _internal.py -> _log line:97 [WARNING]:  * Debugger is active!
[2025-07-27 21:48:39,934.934] _internal.py -> _log line:97 [INFO]:  * Debugger PIN: 222-154-992
[2025-07-27 21:50:44,899.899] http.py -> _register_error_handler line:70 [ERROR]: An error occurred: 404 Not Found: The requested URL was not found on the server. If you entered the URL manually please check your spelling and try again.
Traceback (most recent call last):
  File "/Users/icourt1/.pyenv/versions/llmops-env/lib/python3.10/site-packages/flask/app.py", line 917, in full_dispatch_request
    rv = self.dispatch_request()
  File "/Users/icourt1/.pyenv/versions/llmops-env/lib/python3.10/site-packages/flask/app.py", line 891, in dispatch_request
    self.raise_routing_exception(req)
  File "/Users/icourt1/.pyenv/versions/llmops-env/lib/python3.10/site-packages/flask/app.py", line 500, in raise_routing_exception
    raise request.routing_exception  # type: ignore[misc]
  File "/Users/icourt1/.pyenv/versions/llmops-env/lib/python3.10/site-packages/flask/ctx.py", line 362, in match_request
    result = self.url_adapter.match(return_rule=True)  # type: ignore
  File "/Users/icourt1/.pyenv/versions/llmops-env/lib/python3.10/site-packages/werkzeug/routing/map.py", line 629, in match
    raise NotFound() from None
werkzeug.exceptions.NotFound: 404 Not Found: The requested URL was not found on the server. If you entered the URL manually please check your spelling and try again.
[2025-07-27 21:50:44,911.911] _internal.py -> _log line:97 [INFO]: 127.0.0.1 - - [27/Jul/2025 21:50:44] "[35m[1mPOST /123/debug HTTP/1.1[0m" 500 -
[2025-07-27 21:51:05,473.473] http.py -> _register_error_handler line:70 [ERROR]: An error occurred: 404 Not Found: The requested URL was not found on the server. If you entered the URL manually please check your spelling and try again.
Traceback (most recent call last):
  File "/Users/icourt1/.pyenv/versions/llmops-env/lib/python3.10/site-packages/flask/app.py", line 917, in full_dispatch_request
    rv = self.dispatch_request()
  File "/Users/icourt1/.pyenv/versions/llmops-env/lib/python3.10/site-packages/flask/app.py", line 891, in dispatch_request
    self.raise_routing_exception(req)
  File "/Users/icourt1/.pyenv/versions/llmops-env/lib/python3.10/site-packages/flask/app.py", line 500, in raise_routing_exception
    raise request.routing_exception  # type: ignore[misc]
  File "/Users/icourt1/.pyenv/versions/llmops-env/lib/python3.10/site-packages/flask/ctx.py", line 362, in match_request
    result = self.url_adapter.match(return_rule=True)  # type: ignore
  File "/Users/icourt1/.pyenv/versions/llmops-env/lib/python3.10/site-packages/werkzeug/routing/map.py", line 629, in match
    raise NotFound() from None
werkzeug.exceptions.NotFound: 404 Not Found: The requested URL was not found on the server. If you entered the URL manually please check your spelling and try again.
[2025-07-27 21:51:05,479.479] _internal.py -> _log line:97 [INFO]: 127.0.0.1 - - [27/Jul/2025 21:51:05] "[35m[1mPOST /apps/:app_id/debug HTTP/1.1[0m" 500 -
[2025-07-27 21:51:36,996.996] http.py -> _register_error_handler line:70 [ERROR]: An error occurred: 404 Not Found: The requested URL was not found on the server. If you entered the URL manually please check your spelling and try again.
Traceback (most recent call last):
  File "/Users/icourt1/.pyenv/versions/llmops-env/lib/python3.10/site-packages/flask/app.py", line 917, in full_dispatch_request
    rv = self.dispatch_request()
  File "/Users/icourt1/.pyenv/versions/llmops-env/lib/python3.10/site-packages/flask/app.py", line 891, in dispatch_request
    self.raise_routing_exception(req)
  File "/Users/icourt1/.pyenv/versions/llmops-env/lib/python3.10/site-packages/flask/app.py", line 500, in raise_routing_exception
    raise request.routing_exception  # type: ignore[misc]
  File "/Users/icourt1/.pyenv/versions/llmops-env/lib/python3.10/site-packages/flask/ctx.py", line 362, in match_request
    result = self.url_adapter.match(return_rule=True)  # type: ignore
  File "/Users/icourt1/.pyenv/versions/llmops-env/lib/python3.10/site-packages/werkzeug/routing/map.py", line 629, in match
    raise NotFound() from None
werkzeug.exceptions.NotFound: 404 Not Found: The requested URL was not found on the server. If you entered the URL manually please check your spelling and try again.
[2025-07-27 21:51:37,000.000] _internal.py -> _log line:97 [INFO]: 127.0.0.1 - - [27/Jul/2025 21:51:37] "[35m[1mPOST /apps/:app_id/debug HTTP/1.1[0m" 500 -
[2025-07-27 21:51:50,735.735] _internal.py -> _log line:97 [INFO]: 127.0.0.1 - - [27/Jul/2025 21:51:50] "GET /ping HTTP/1.1" 200 -
[2025-07-27 21:52:01,569.569] http.py -> _register_error_handler line:70 [ERROR]: An error occurred: 404 Not Found: The requested URL was not found on the server. If you entered the URL manually please check your spelling and try again.
Traceback (most recent call last):
  File "/Users/icourt1/.pyenv/versions/llmops-env/lib/python3.10/site-packages/flask/app.py", line 917, in full_dispatch_request
    rv = self.dispatch_request()
  File "/Users/icourt1/.pyenv/versions/llmops-env/lib/python3.10/site-packages/flask/app.py", line 891, in dispatch_request
    self.raise_routing_exception(req)
  File "/Users/icourt1/.pyenv/versions/llmops-env/lib/python3.10/site-packages/flask/app.py", line 500, in raise_routing_exception
    raise request.routing_exception  # type: ignore[misc]
  File "/Users/icourt1/.pyenv/versions/llmops-env/lib/python3.10/site-packages/flask/ctx.py", line 362, in match_request
    result = self.url_adapter.match(return_rule=True)  # type: ignore
  File "/Users/icourt1/.pyenv/versions/llmops-env/lib/python3.10/site-packages/werkzeug/routing/map.py", line 629, in match
    raise NotFound() from None
werkzeug.exceptions.NotFound: 404 Not Found: The requested URL was not found on the server. If you entered the URL manually please check your spelling and try again.
[2025-07-27 21:52:01,578.578] _internal.py -> _log line:97 [INFO]: 127.0.0.1 - - [27/Jul/2025 21:52:01] "[35m[1mPOST /apps/q1231231/debug HTTP/1.1[0m" 500 -
[2025-07-27 21:52:12,935.935] http.py -> _register_error_handler line:70 [ERROR]: An error occurred: 404 Not Found: The requested URL was not found on the server. If you entered the URL manually please check your spelling and try again.
Traceback (most recent call last):
  File "/Users/icourt1/.pyenv/versions/llmops-env/lib/python3.10/site-packages/flask/app.py", line 917, in full_dispatch_request
    rv = self.dispatch_request()
  File "/Users/icourt1/.pyenv/versions/llmops-env/lib/python3.10/site-packages/flask/app.py", line 891, in dispatch_request
    self.raise_routing_exception(req)
  File "/Users/icourt1/.pyenv/versions/llmops-env/lib/python3.10/site-packages/flask/app.py", line 500, in raise_routing_exception
    raise request.routing_exception  # type: ignore[misc]
  File "/Users/icourt1/.pyenv/versions/llmops-env/lib/python3.10/site-packages/flask/ctx.py", line 362, in match_request
    result = self.url_adapter.match(return_rule=True)  # type: ignore
  File "/Users/icourt1/.pyenv/versions/llmops-env/lib/python3.10/site-packages/werkzeug/routing/map.py", line 629, in match
    raise NotFound() from None
werkzeug.exceptions.NotFound: 404 Not Found: The requested URL was not found on the server. If you entered the URL manually please check your spelling and try again.
[2025-07-27 21:52:12,941.941] _internal.py -> _log line:97 [INFO]: 127.0.0.1 - - [27/Jul/2025 21:52:12] "[35m[1mPOST /apps/q1231231/debug HTTP/1.1[0m" 500 -
[2025-07-27 21:53:19,067.067] _internal.py -> _log line:97 [INFO]: 127.0.0.1 - - [27/Jul/2025 21:53:19] "POST /apps/6c5e3fd6-6307-4eb5-b017-895b25ce4a1c/debug HTTP/1.1" 200 -
[2025-07-27 21:54:14,011.011] _internal.py -> _log line:97 [INFO]: 127.0.0.1 - - [27/Jul/2025 21:54:14] "POST /apps/6c5e3fd6-6307-4eb5-b017-895b25ce4a1c/debug HTTP/1.1" 200 -
[2025-07-27 23:55:38,915.915] _internal.py -> _log line:97 [INFO]:  * Detected change in '/Users/icourt1/Desktop/code/llmops/llmops-api/internal/service/conversation_service.py', reloading
[2025-07-27 23:55:39,397.397] _internal.py -> _log line:97 [INFO]:  * Restarting with stat
[2025-07-27 23:55:42,301.301] _internal.py -> _log line:97 [WARNING]:  * Debugger is active!
[2025-07-27 23:55:42,318.318] _internal.py -> _log line:97 [INFO]:  * Debugger PIN: 222-154-992
