[2025-07-08 00:00:18,185.185] base.py -> _begin_impl line:1097 [INFO]: BEGIN (implicit)
[2025-07-08 00:00:18,187.187] base.py -> _exec_single_context line:1896 [INFO]: SELECT dataset.id AS dataset_id, dataset.account_id AS dataset_account_id, dataset.name AS dataset_name, dataset.icon AS dataset_icon, dataset.description AS dataset_description, dataset.updated_at AS dataset_updated_at, dataset.created_at AS dataset_created_at 
FROM dataset 
WHERE dataset.id = %(pk_1)s::UUID
[2025-07-08 00:00:18,187.187] base.py -> _exec_single_context line:1901 [INFO]: [cached since 363s ago] {'pk_1': UUID('dcaf5254-6ebe-4fae-9d95-38a3d3a27b9c')}
[2025-07-08 00:00:18,192.192] base.py -> _rollback_impl line:1123 [INFO]: ROLLBACK
[2025-07-08 00:00:18,193.193] dataset_service.py -> delete_dataset line:137 [ERROR]: 删除知识库失败, dataset_id: dcaf5254-6ebe-4fae-9d95-38a3d3a27b9c, 错误信息: subject table for an INSERT, UPDATE or DELETE expected, got <Dataset dcaf5254-6ebe-4fae-9d95-38a3d3a27b9c>.
Traceback (most recent call last):
  File "/Users/icourt1/Desktop/code/llmops/llmops-api/internal/service/dataset_service.py", line 128, in delete_dataset
    self.delete(dataset)
  File "/Users/icourt1/Desktop/code/llmops/llmops-api/internal/service/base_service.py", line 27, in delete
    self.db.delete(model_instance)
  File "/Users/icourt1/.pyenv/versions/llmops-env/lib/python3.10/site-packages/sqlalchemy/sql/_dml_constructors.py", line 132, in delete
    return Delete(table)
  File "/Users/icourt1/.pyenv/versions/llmops-env/lib/python3.10/site-packages/sqlalchemy/sql/dml.py", line 1734, in __init__
    self.table = coercions.expect(
  File "/Users/icourt1/.pyenv/versions/llmops-env/lib/python3.10/site-packages/sqlalchemy/sql/coercions.py", line 392, in expect
    impl._raise_for_expected(original_element, argname)
  File "/Users/icourt1/.pyenv/versions/llmops-env/lib/python3.10/site-packages/sqlalchemy/sql/coercions.py", line 695, in _raise_for_expected
    super()._raise_for_expected(
  File "/Users/icourt1/.pyenv/versions/llmops-env/lib/python3.10/site-packages/sqlalchemy/sql/coercions.py", line 518, in _raise_for_expected
    raise exc.ArgumentError(msg, code=code) from err
sqlalchemy.exc.ArgumentError: subject table for an INSERT, UPDATE or DELETE expected, got <Dataset dcaf5254-6ebe-4fae-9d95-38a3d3a27b9c>.
[2025-07-08 00:00:18,194.194] http.py -> _register_error_handler line:70 [ERROR]: An error occurred: 
Traceback (most recent call last):
  File "/Users/icourt1/Desktop/code/llmops/llmops-api/internal/service/dataset_service.py", line 128, in delete_dataset
    self.delete(dataset)
  File "/Users/icourt1/Desktop/code/llmops/llmops-api/internal/service/base_service.py", line 27, in delete
    self.db.delete(model_instance)
  File "/Users/icourt1/.pyenv/versions/llmops-env/lib/python3.10/site-packages/sqlalchemy/sql/_dml_constructors.py", line 132, in delete
    return Delete(table)
  File "/Users/icourt1/.pyenv/versions/llmops-env/lib/python3.10/site-packages/sqlalchemy/sql/dml.py", line 1734, in __init__
    self.table = coercions.expect(
  File "/Users/icourt1/.pyenv/versions/llmops-env/lib/python3.10/site-packages/sqlalchemy/sql/coercions.py", line 392, in expect
    impl._raise_for_expected(original_element, argname)
  File "/Users/icourt1/.pyenv/versions/llmops-env/lib/python3.10/site-packages/sqlalchemy/sql/coercions.py", line 695, in _raise_for_expected
    super()._raise_for_expected(
  File "/Users/icourt1/.pyenv/versions/llmops-env/lib/python3.10/site-packages/sqlalchemy/sql/coercions.py", line 518, in _raise_for_expected
    raise exc.ArgumentError(msg, code=code) from err
sqlalchemy.exc.ArgumentError: subject table for an INSERT, UPDATE or DELETE expected, got <Dataset dcaf5254-6ebe-4fae-9d95-38a3d3a27b9c>.

During handling of the above exception, another exception occurred:

Traceback (most recent call last):
  File "/Users/icourt1/.pyenv/versions/llmops-env/lib/python3.10/site-packages/flask/app.py", line 917, in full_dispatch_request
    rv = self.dispatch_request()
  File "/Users/icourt1/.pyenv/versions/llmops-env/lib/python3.10/site-packages/flask/app.py", line 902, in dispatch_request
    return self.ensure_sync(self.view_functions[rule.endpoint])(**view_args)  # type: ignore[no-any-return]
  File "/Users/icourt1/Desktop/code/llmops/llmops-api/internal/handler/dataset_handler.py", line 81, in delete_dataset
    self.dataset_service.delete_dataset(dataset_id)
  File "/Users/icourt1/Desktop/code/llmops/llmops-api/internal/service/dataset_service.py", line 138, in delete_dataset
    raise FailException("删除知识库失败，请稍后重试")
internal.exception.exception.FailException
[2025-07-08 00:00:18,196.196] _internal.py -> _log line:97 [INFO]: 127.0.0.1 - - [08/Jul/2025 00:00:18] "POST /datasets/dcaf5254-6ebe-4fae-9d95-38a3d3a27b9c/delete HTTP/1.1" 200 -
[2025-07-08 00:00:58,444.444] _internal.py -> _log line:97 [INFO]:  * Detected change in '/Users/icourt1/Desktop/code/llmops/llmops-api/internal/service/dataset_service.py', reloading
